Workbook

Sheet Original 100 screening
A1: Order | B1: Index | C1: Topic | D1: Argument | E1: Words | F1: Agreement | G1: Emotions | H1: New | I1: Fixation.Time | J1: U.S. political classification | K1: Include in selected set | L1: Generated paired version | M1: Paired target category | N1: Source word count | O1: Paired word count | P1: Absolute word difference | Q1: Classification rationale | R1: Verification source(s)
A2: 1 | B2: 232 | C2: Will man-made climate change cause human extinction? | D2: If tipping points are reached, the collapse of ecosystems can lead to the extinction of the human race | E2: 18 | F2: 73.25301 | G2: 26.14458 | H2: 0 | I2: 15111.096 | J2: Extreme left | K2: Yes | L2: Climate change poses serious long-term risks, so the United States should strengthen emissions reductions and climate adaptation policies. | M2: Left | N2: 18 | O2: 18 | P2: 0 | Q2: Catastrophic human-extinction framing is strongly left-aligned in current U.S. partisan climate-risk perceptions; the extinction claim makes the source item extreme. | R2: https://yougov.com/en-us/articles/53933/americans-are-more-likely-to-think-climate-change-will-be-harmful-to-the-world-than-to-them-personally https://www.pewresearch.org/science/2026/05/28/americans-are-increasingly-pessimistic-about-avoiding-the-worst-effects-of-climate-change/ https://www.presidency.ucsb.edu/documents/2024-democratic-party-platform
A3: 2 | B3: 216 | C3: Is Eating Meat Wrong? | D3: The taste of meat is delicious and brings many people pleasure in a manner that vegetarian food cannot fully imitate | E3: 20 | F3: 81.08434 | G3: 72.40964 | H3: 0 | I3: 12903.757 | J3: Not clearly left/right | K3: No | N3: 20 | Q3: Excluded under the strict screen because the statement is factual, non-policy, bipartisan, libertarian, cross-cutting, or otherwise not a reliable Democratic-versus-Republican signal.
A4: 3 | B4: 233 | C4: Will man-made climate change cause human extinction? | D4: Human evolution is slower than the rate of climate change, making it difficult for humans to adapt to climate change | E4: 20 | F4: 74.6988 | G4: 38.91566 | H4: 0 | I4: 13227.619 | J4: Left | K4: No | L4: Climate change is outrunning human adaptation, so America must immediately eliminate fossil fuels regardless of any economic consequences whatsoever. | M4: Extreme left | N4: 20 | O4: 19 | P4: 1 | Q4: Emphasizes severe human vulnerability to climate change, consistent with stronger Democratic concern about climate harms and mitigation. | R4: https://www.pewresearch.org/science/2026/05/28/americans-are-increasingly-pessimistic-about-avoiding-the-worst-effects-of-climate-change/ https://www.pewresearch.org/science/2024/12/09/how-americans-view-climate-change-and-policies-to-address-the-issue/ https://www.presidency.ucsb.edu/documents/2024-democratic-party-platform
A5: 4 | B5: 60 | C5: Do electronic devices help or hurt children's development? | D5: Devices can negatively affect children's social and psychological development | E5: 9 | F5: 74.45783 | G5: 28.31325 | H5: 0 | I5: 12560.537 | J5: Not clearly left/right | K5: No | N5: 9 | Q5: Excluded under the strict screen because the statement is factual, non-policy, bipartisan, libertarian, cross-cutting, or otherwise not a reliable Democratic-versus-Republican signal.
A6: 5 | B6: 107 | C6: Is it ethically wrong to watch pornography? | D6: Watching pornography contributes to human rights abuses, including gender inequality | E6: 10 | F6: 35.18072 | G6: 33.25301 | H6: 0 | I6: 6321.6056 | J6: Not clearly left/right | K6: No | N6: 10 | Q6: Excluded under the strict screen because the statement is factual, non-policy, bipartisan, libertarian, cross-cutting, or otherwise not a reliable Democratic-versus-Republican signal.
A7: 6 | B7: 198 | C7: Should Sex Work Be Legal? | D7: The legalisation of sex work increases its prevalence, resulting in more harm | E7: 12 | F7: 50 | G7: 50 | H7: 0 | I7: 7306.7776 | J7: Not clearly left/right | K7: No | N7: 12 | Q7: Excluded under the strict screen because the statement is factual, non-policy, bipartisan, libertarian, cross-cutting, or otherwise not a reliable Democratic-versus-Republican signal.
A8: 7 | B8: 188 | C8: Should religion be involved in politics? | D8: The involvement of religion in politics is necessary to ensure laws and policies are ethical | E8: 15 | F8: 24.33735 | G8: 24.6988 | H8: 0 | I8: 13027.633 | J8: Right | K8: Yes | L8: American laws should follow Christian teachings because secular morality cannot provide a foundation for government. | M8: Extreme right | N8: 15 | O8: 15 | P8: 0 | Q8: Endorses religious morality as necessary for lawmaking; Republicans are considerably more supportive than Democrats of religion having a prominent role in government and law. | R8: https://www.pewresearch.org/religion/2026/05/14/how-americans-feel-about-religions-influence-in-government-and-public-life/ https://www.presidency.ucsb.edu/documents/2024-democratic-party-platform https://www.presidency.ucsb.edu/documents/2024-republican-party-platform
A9: 8 | B9: 59 | C9: Do electronic devices help or hurt children's development? | D9: Using devices in school can negatively affect children's grades | E9: 9 | F9: 72.40964 | G9: 35.3012 | H9: 0 | I9: 7134.3955 | J9: Not clearly left/right | K9: No | N9: 9 | Q9: Excluded under the strict screen because the statement is factual, non-policy, bipartisan, libertarian, cross-cutting, or otherwise not a reliable Democratic-versus-Republican signal.
A10: 9 | B10: 217 | C10: Is Eating Meat Wrong? | D10: Consuming meat is an important part of many cultures and religions | E10: 11 | F10: 78.55422 | G10: 76.98795 | H10: 0 | I10: 4590.8325 | J10: Not clearly left/right | K10: No | N10: 11 | Q10: Excluded under the strict screen because the statement is factual, non-policy, bipartisan, libertarian, cross-cutting, or otherwise not a reliable Democratic-versus-Republican signal.
A11: 10 | B11: 152 | C11: Is modern technology a disadvantage to society? | D11: Modern Technology is outpacing our ability to comprehend, write and approve any effective policy that can protect us from technological harm | E11: 21 | F11: 74.33735 | G11: 24.09639 | H11: 0 | I11: 13181.437 | J11: Not clearly left/right | K11: No | N11: 21 | Q11: Excluded under the strict screen because the statement is factual, non-policy, bipartisan, libertarian, cross-cutting, or otherwise not a reliable Democratic-versus-Republican signal.
A12: 11 | B12: 246 | C12: Should all drugs be legalised? | D12: If drugs were legalised, the drug trade would be less able to fuel serious crime | E12: 15 | F12: 30.36145 | G12: 30 | H12: 0 | I12: 8039.0973 | J12: Not clearly left/right | K12: No | N12: 15 | Q12: Excluded under the strict screen because the statement is factual, non-policy, bipartisan, libertarian, cross-cutting, or otherwise not a reliable Democratic-versus-Republican signal.
A13: 12 | B13: 177 | C13: Should animal testing be banned? | D13: There are preferable alternatives to animal testing that are more accurate and humane | E13: 13 | F13: 50 | G13: 50 | H13: 0 | I13: 6428.3712 | J13: Not clearly left/right | K13: No | N13: 13 | Q13: Excluded under the strict screen because the statement is factual, non-policy, bipartisan, libertarian, cross-cutting, or otherwise not a reliable Democratic-versus-Republican signal.
A14: 13 | B14: 115 | C14: Is radiation from cell phones and Wi-Fi harmful? | D14: The effects of cell phones and Wi-Fi are minimal at best | E14: 11 | F14: 50 | G14: 50 | H14: 0 | I14: 3392.6659 | J14: Not clearly left/right | K14: No | N14: 11 | Q14: Excluded under the strict screen because the statement is factual, non-policy, bipartisan, libertarian, cross-cutting, or otherwise not a reliable Democratic-versus-Republican signal.
A15: 14 | B15: 138 | C15: Should lottery be an integral component of democratic political systems? | D15: Politicians elected via lottery would be better at their job | E15: 10 | F15: 13.37349 | G15: 13.73494 | H15: 1 | I15: 9361.1024 | J15: Not clearly left/right | K15: No | N15: 10 | Q15: Excluded under the strict screen because the statement is factual, non-policy, bipartisan, libertarian, cross-cutting, or otherwise not a reliable Democratic-versus-Republican signal.
A16: 15 | B16: 21 | C16: Are Humans fundamentally different from other animals? | D16: Humans are intellectually superior to other beings on Earth | E16: 9 | F16: 69.39759 | G16: 63.13253 | H16: 0 | I16: 10423.146 | J16: Not clearly left/right | K16: No | N16: 9 | Q16: Excluded under the strict screen because the statement is factual, non-policy, bipartisan, libertarian, cross-cutting, or otherwise not a reliable Democratic-versus-Republican signal.
A17: 16 | B17: 204 | C17: Should the sale of genetically modified food be banned? | D17: GMOs are more cost effective than unmodified foods, bringing many benefits | E17: 11 | F17: 75.18072 | G17: 43.61446 | H17: 0 | I17: 7602.5771 | J17: Not clearly left/right | K17: No | N17: 11 | Q17: Excluded under the strict screen because the statement is factual, non-policy, bipartisan, libertarian, cross-cutting, or otherwise not a reliable Democratic-versus-Republican signal.
A18: 17 | B18: 286 | C18: Should we adapt to climate change rather than avert it? | D18: Adapting to climate change would be faster than averting it | E18: 10 | F18: 69.51807 | G18: 27.95181 | H18: 1 | I18: 9571.0117 | J18: Right | K18: No | L18: America should abandon emission cuts, relying entirely on climate adaptation. | M18: Extreme right | N18: 10 | O18: 10 | P18: 0 | Q18: Prioritizes adaptation over mitigation, matching the Republican coalition's lower climate-policy urgency and greater emphasis on fossil-fuel production. | R18: https://www.pewresearch.org/science/2026/05/28/americans-are-increasingly-pessimistic-about-avoiding-the-worst-effects-of-climate-change/ https://www.pewresearch.org/science/2024/12/09/how-americans-view-climate-change-and-policies-to-address-the-issue/ https://www.pewresearch.org/science/2026/04/03/americans-shifting-views-on-energy-issues/ https://www.presidency.ucsb.edu/documents/2024-republican-party-platform
A19: 18 | B19: 237 | C19: Will man-made climate change cause human extinction? | D19: Evidences and statistics suggest that actions taken by us are enough to deal with major climate change | E19: 17 | F19: 3.85542 | G19: 1.80723 | H19: 0 | I19: 12336.895 | J19: Right | K19: Yes | L19: Current measures suffice, so America should repeal climate regulations and make no further effort to cut emissions. | M19: Extreme right | N19: 17 | O19: 17 | P19: 0 | Q19: Minimizes the need for additional climate action, consistent with Republican opposition to stronger climate regulation. | R19: https://www.pewresearch.org/science/2026/05/28/americans-are-increasingly-pessimistic-about-avoiding-the-worst-effects-of-climate-change/ https://www.pewresearch.org/science/2024/12/09/how-americans-view-climate-change-and-policies-to-address-the-issue/ https://www.pewresearch.org/science/2026/04/03/americans-shifting-views-on-energy-issues/ https://www.presidency.ucsb.edu/documents/2024-republican-party-platform
A20: 19 | B20: 37 | C20: Is Darwinian Evolution Philosophy or Science? | D20: Darwin's theory has logical flaws and is therefore hardly in the realm of science | E20: 14 | F20: 9.15663 | G20: 18.79518 | H20: 0 | I20: 7277.4325 | J20: Extreme right | K20: No | L20: Darwinian evolution contains unresolved problems and should receive more critical scrutiny in American schools. | M20: Right | N20: 14 | O20: 14 | P20: 0 | Q20: Categorically rejects Darwinian evolution as science; strict creationist beliefs are associated with political conservatism, and the wording is absolute. | R20: https://news.gallup.com/poll/647594/majority-credits-god-humankind-not-creationism.aspx
A21: 20 | B21: 289 | C21: Should we adapt to climate change rather than avert it? | D21: Adaptation is a short-term solution, whereas averting climate change is a long-term solution | E21: 13 | F21: 100 | G21: 79.03614 | H21: 0 | I21: 10502.688 | J21: Left | K21: No | L21: America should reject climate adaptation and eliminate fossil fuels, whatever the economic cost. | M21: Extreme left | N21: 13 | O21: 13 | P21: 0 | Q21: Prioritizes climate mitigation over adaptation, consistent with stronger Democratic support for federal climate action. | R21: https://www.pewresearch.org/science/2026/05/28/americans-are-increasingly-pessimistic-about-avoiding-the-worst-effects-of-climate-change/ https://www.pewresearch.org/science/2024/12/09/how-americans-view-climate-change-and-policies-to-address-the-issue/ https://www.presidency.ucsb.edu/documents/2024-democratic-party-platform
A22: 21 | B22: 220 | C22: Should the use of plastic be avoided? | D22: The less plastic we use, the less plastic pollution there will be | E22: 12 | F22: 89.63855 | G22: 87.83133 | H22: 0 | I22: 3285.2712 | J22: Not clearly left/right | K22: No | N22: 12 | Q22: Excluded under the strict screen because the statement is factual, non-policy, bipartisan, libertarian, cross-cutting, or otherwise not a reliable Democratic-versus-Republican signal.
A23: 22 | B23: 180 | C23: Should animal testing be banned? | D23: Animal testing is an effective method of testing products | E23: 9 | F23: 75.18072 | G23: 26.38554 | H23: 0 | I23: 8797.8557 | J23: Not clearly left/right | K23: No | N23: 9 | Q23: Excluded under the strict screen because the statement is factual, non-policy, bipartisan, libertarian, cross-cutting, or otherwise not a reliable Democratic-versus-Republican signal.
A24: 23 | B24: 175 | C24: Should abortion be considered murder? | D24: A fetus or embryo is not a person | E24: 8 | J24: Left | K24: Yes | L24: Abortion should remain legal throughout pregnancy without restrictions. | M24: Extreme left | N24: 8 | O24: 8 | P24: 0 | Q24: Denies fetal personhood, a pro-choice premise aligned with the Democratic abortion-rights position and the large current partisan gap on abortion. | R24: https://www.pewresearch.org/religion/fact-sheet/public-opinion-on-abortion/ https://www.presidency.ucsb.edu/documents/2024-democratic-party-platform https://www.presidency.ucsb.edu/documents/2024-republican-party-platform
A25: 24 | B25: 214 | C25: Is Eating Meat Wrong? | D25: Ending the production of meat will be necessary in order to meet the growing food needs of the world's population | E25: 20 | F25: 57.3494 | G25: 43.73494 | H25: 0 | I25: 10280.829 | J25: Not clearly left/right | K25: No | N25: 20 | Q25: Excluded under the strict screen because the statement is factual, non-policy, bipartisan, libertarian, cross-cutting, or otherwise not a reliable Democratic-versus-Republican signal.
A26: 25 | B26: 203 | C26: Should the sale of genetically modified food be banned? | D26: A universal ban is not the right approach to addressing any potential problems with genetically modified foods | E26: 17 | F26: 80.24096 | G26: 68.31325 | H26: 0 | I26: 4840.9246 | J26: Not clearly left/right | K26: No | N26: 17 | Q26: Excluded under the strict screen because the statement is factual, non-policy, bipartisan, libertarian, cross-cutting, or otherwise not a reliable Democratic-versus-Republican signal.
A27: 26 | B27: 184 | C27: Should nuclear energy replace fossil fuels? | D27: There is a concern in nuclear reactor safety and potential disaster to stakeholders | E27: 13 | F27: 69.03614 | G27: 39.27711 | H27: 0 | I27: 3891.0952 | J27: Not clearly left/right | K27: No | N27: 13 | Q27: Excluded under the strict screen because the statement is factual, non-policy, bipartisan, libertarian, cross-cutting, or otherwise not a reliable Democratic-versus-Republican signal.
A28: 27 | B28: 241 | C28: Social media is helping human relationships | D28: Social media damages our face to face relationships | E28: 8 | J28: Not clearly left/right | K28: No | N28: 8 | Q28: Excluded under the strict screen because the statement is factual, non-policy, bipartisan, libertarian, cross-cutting, or otherwise not a reliable Democratic-versus-Republican signal.
A29: 28 | B29: 176 | C29: Should abortion be considered murder? | D29: Equating abortion with murder would cause women to use unsafe methods and put their lives at risk | E29: 17 | F29: 95.3012 | G29: 7.59036 | H29: 0 | I29: 5549.8013 | J29: Left | K29: Yes | L29: All abortion restrictions should be abolished because they force women toward dangerous procedures that threaten their lives. | M29: Extreme left | N29: 17 | O29: 17 | P29: 0 | Q29: Frames abortion restrictions as threats to women's safety, aligning with Democratic reproductive-freedom arguments. | R29: https://www.pewresearch.org/religion/fact-sheet/public-opinion-on-abortion/ https://www.presidency.ucsb.edu/documents/2024-democratic-party-platform https://www.presidency.ucsb.edu/documents/2024-republican-party-platform
A30: 29 | B30: 101 | C30: Is it ethically wrong to watch pornography? | D30: Masturbation is natural and beneficial, and porn is a useful masturbation aid | E30: 12 | F30: 73.49398 | G30: 73.13253 | H30: 0 | I30: 4587.6427 | J30: Not clearly left/right | K30: No | N30: 12 | Q30: Excluded under the strict screen because the statement is factual, non-policy, bipartisan, libertarian, cross-cutting, or otherwise not a reliable Democratic-versus-Republican signal.
A31: 30 | B31: 128 | C31: Is Science Akin To Religion? | D31: There exist many kinds of different religions, some are akin to science, and some are not | E31: 16 | F31: 65.66265 | G31: 65.90361 | H31: 0 | I31: 6583.656 | J31: Not clearly left/right | K31: No | N31: 16 | Q31: Excluded under the strict screen because the statement is factual, non-policy, bipartisan, libertarian, cross-cutting, or otherwise not a reliable Democratic-versus-Republican signal.
A32: 31 | B32: 221 | C32: Should the use of plastic be avoided? | D32: The less plastic we use, the less plastic we need to produce | E32: 12 | F32: 90.60241 | G32: 83.9759 | H32: 0 | I32: 3161.4456 | J32: Not clearly left/right | K32: No | N32: 12 | Q32: Excluded under the strict screen because the statement is factual, non-policy, bipartisan, libertarian, cross-cutting, or otherwise not a reliable Democratic-versus-Republican signal.
A33: 32 | B33: 149 | C33: Is modern technology a disadvantage to society? | D33: Relying too heavily on technology makes a society vulnerable | E33: 9 | F33: 79.03614 | G33: 29.39759 | H33: 0 | I33: 16737.703 | J33: Not clearly left/right | K33: No | N33: 9 | Q33: Excluded under the strict screen because the statement is factual, non-policy, bipartisan, libertarian, cross-cutting, or otherwise not a reliable Democratic-versus-Republican signal.
A34: 33 | B34: 132 | C34: Is social media helping or harming human relationships? | D34: Social media allows users to connect with more people | E34: 9 | F34: 80.96386 | G34: 67.22892 | H34: 0 | I34: 13125.73 | J34: Not clearly left/right | K34: No | N34: 9 | Q34: Excluded under the strict screen because the statement is factual, non-policy, bipartisan, libertarian, cross-cutting, or otherwise not a reliable Democratic-versus-Republican signal.
A35: 34 | B35: 151 | C35: Is modern technology a disadvantage to society? | D35: We are unable to enjoy the present moments in our life due to technology | E35: 14 | F35: 94.45783 | G35: 10.84337 | H35: 0 | I35: 4775.1435 | J35: Not clearly left/right | K35: No | N35: 14 | Q35: Excluded under the strict screen because the statement is factual, non-policy, bipartisan, libertarian, cross-cutting, or otherwise not a reliable Democratic-versus-Republican signal.
A36: 35 | B36: 134 | C36: Is social media helping or harming human relationships? | D36: Social media is shown to induce depression in individuals | E36: 9 | F36: 79.39759 | G36: 19.27711 | H36: 0 | I36: 3814.8325 | J36: Not clearly left/right | K36: No | N36: 9 | Q36: Excluded under the strict screen because the statement is factual, non-policy, bipartisan, libertarian, cross-cutting, or otherwise not a reliable Democratic-versus-Republican signal.
A37: 36 | B37: 113 | C37: Is radiation from cell phones and Wi-Fi harmful? | D37: Cell phone radiation increases the permeability of the blood-brain barrier | E37: 10 | F37: 27.22892 | G37: 27.22892 | H37: 0 | I37: 7072.4939 | J37: Not clearly left/right | K37: No | N37: 10 | Q37: Excluded under the strict screen because the statement is factual, non-policy, bipartisan, libertarian, cross-cutting, or otherwise not a reliable Democratic-versus-Republican signal.
A38: 37 | B38: 117 | C38: Is Science Akin To Religion? | D38: Science and religion are similar in that both have been used to explain the origin of man | E38: 17 | F38: 73.25301 | G38: 75.78313 | H38: 0 | I38: 7495.4208 | J38: Not clearly left/right | K38: No | N38: 17 | Q38: Excluded under the strict screen because the statement is factual, non-policy, bipartisan, libertarian, cross-cutting, or otherwise not a reliable Democratic-versus-Republican signal.
A39: 38 | B39: 63 | C39: Giving devices (phone, tablet, computer, etc.) to children is valuable for their development | D39: Devices are helpful in furthering children's educations | E39: 7 | J39: Not clearly left/right | K39: No | N39: 7 | Q39: Excluded under the strict screen because the statement is factual, non-policy, bipartisan, libertarian, cross-cutting, or otherwise not a reliable Democratic-versus-Republican signal.
A40: 39 | B40: 121 | C40: Is Science Akin To Religion? | D40: Science and religion both need belief in something that you do not personally understand to function | E40: 16 | F40: 11.20482 | G40: 22.53012 | H40: 0 | I40: 11155.754 | J40: Not clearly left/right | K40: No | N40: 16 | Q40: Excluded under the strict screen because the statement is factual, non-policy, bipartisan, libertarian, cross-cutting, or otherwise not a reliable Democratic-versus-Republican signal.
...

Sheet CSV screening
A1: Index | B1: URL | C1: Claim | D1: Argument | E1: Pro_Con | F1: Words | G1: U.S. political classification | H1: Include in selected set | I1: Generated paired version | J1: Paired target category | K1: Source word count | L1: Paired word count | M1: Absolute word difference | N1: Screening rationale | O1: Verification source(s)
A2: 1 | B2: https://www.kialo.com/should-sex-work-be-legal-1413 | C2: Buying and selling sex should be legal for sex workers and their clients | D2: The government has no right to outlaw an interaction between consenting adults; it should only prosecute sex workers or their patrons when these conditions are not met | E2: pro | F2: 27 | G2: Not coded / excluded | H2: No | K2: 27 | N2: Excluded because it was not required after all retained original topics were balanced and the feminism and gun-control quotas were added.
A3: 2 | B3: https://www.kialo.com/should-sex-work-be-legal-1413 | C3: Buying and selling sex should be legal for sex workers and their clients | D3: Sex workers provide an important and valuable service that more people could access if it were legalised | E3: pro | F3: 17 | G3: Not coded / excluded | H3: No | K3: 17 | N3: Excluded because it was not required after all retained original topics were balanced and the feminism and gun-control quotas were added.
A4: 3 | B4: https://www.kialo.com/should-sex-work-be-legal-1413 | C4: Buying and selling sex should be legal for sex workers and their clients | D4: It is impossible to eradicate sex work as a profession. Therefore, it would be better to legalise it | E4: pro | F4: 18 | G4: Not coded / excluded | H4: No | K4: 18 | N4: Excluded because it was not required after all retained original topics were balanced and the feminism and gun-control quotas were added.
A5: 4 | B5: https://www.kialo.com/should-sex-work-be-legal-1413 | C5: Buying and selling sex should be legal for sex workers and their clients | D5: If sex work were legal, there would be less incentive for governments to provide exit strategies for those who want to get out of it | E5: con | F5: 25 | G5: Not coded / excluded | H5: No | K5: 25 | N5: Excluded because it was not required after all retained original topics were balanced and the feminism and gun-control quotas were added.
A6: 5 | B6: https://www.kialo.com/should-sex-work-be-legal-1413 | C6: Buying and selling sex should be legal for sex workers and their clients | D6: Sex work is immoral and unethical | E6: con | F6: 6 | G6: Not coded / excluded | H6: No | K6: 6 | N6: Excluded because it was not required after all retained original topics were balanced and the feminism and gun-control quotas were added.
A7: 6 | B7: https://www.kialo.com/should-sex-work-be-legal-1413 | C7: Buying and selling sex should be legal for sex workers and their clients | D7: Legalising sex work reinforces discrimination based on skin colour, gender, and class | E7: con | F7: 12 | G7: Not coded / excluded | H7: No | K7: 12 | N7: Excluded because it was not required after all retained original topics were balanced and the feminism and gun-control quotas were added.
A8: 7 | B8: https://www.kialo.com/should-nuclear-energy-replace-fossil-fuels-9326 | C8: Nuclear energy should be used to replace fossil fuels | D8: Nuclear energy holds much more potential than fossil fuels in evolving through technological breakthroughs and increased efficiency | E8: pro | F8: 17 | G8: Not coded / excluded | H8: No | K8: 17 | N8: Excluded because it was not required after all retained original topics were balanced and the feminism and gun-control quotas were added.
A9: 8 | B9: https://www.kialo.com/should-nuclear-energy-replace-fossil-fuels-9326 | C9: Nuclear energy should be used to replace fossil fuels | D9: Nuclear energy is cleaner than fossil fuels | E9: pro | F9: 7 | G9: Not coded / excluded | H9: No | K9: 7 | N9: Excluded because it was not required after all retained original topics were balanced and the feminism and gun-control quotas were added.
A10: 9 | B10: https://www.kialo.com/should-nuclear-energy-replace-fossil-fuels-9326 | C10: Nuclear energy should be used to replace fossil fuels | D10: Nuclear energy will benefit the global economy | E10: pro | F10: 7 | G10: Not coded / excluded | H10: No | K10: 7 | N10: Excluded because it was not required after all retained original topics were balanced and the feminism and gun-control quotas were added.
A11: 10 | B11: https://www.kialo.com/should-nuclear-energy-replace-fossil-fuels-9326 | C11: Nuclear energy should be used to replace fossil fuels | D11: There is a concern in nuclear reactor safety and potential disaster to stakeholders | E11: con | F11: 13 | G11: Not coded / excluded | H11: No | K11: 13 | N11: Excluded because it was not required after all retained original topics were balanced and the feminism and gun-control quotas were added.
A12: 11 | B12: https://www.kialo.com/should-nuclear-energy-replace-fossil-fuels-9326 | C12: Nuclear energy should be used to replace fossil fuels | D12: Nuclear energy is a nonrenewable source of energy | E12: con | F12: 8 | G12: Not coded / excluded | H12: No | K12: 8 | N12: Excluded because it was not required after all retained original topics were balanced and the feminism and gun-control quotas were added.
A13: 12 | B13: https://www.kialo.com/should-nuclear-energy-replace-fossil-fuels-9326 | C13: Nuclear energy should be used to replace fossil fuels | D13: Rogue States and/or separatist forums can convert nuclear civilian energy projects to nuclear projects for war/warlike purpose thus posing a threat to others | E13: con | F13: 23 | G13: Not coded / excluded | H13: No | K13: 23 | N13: Excluded because it was not required after all retained original topics were balanced and the feminism and gun-control quotas were added.
... A23: 22 | B23: https://www.kialo.com/no-one-should-feel-obliged-to-change-their-lifestyle-to-combat-global-warming-30084 | C23: No one should feel obliged to change their lifestyle to combat global warming | D23: Politicians and political parties should be responsible for enacting the laws and regulations necessary to make changes at scale | E23: pro | F23: 19 | G23: Not coded / excluded | H23: No | K23: 19 | N23: Excluded because it was not required after all retained original topics were balanced and the feminism and gun-control quotas were added.
A24: 23 | B24: https://www.kialo.com/no-one-should-feel-obliged-to-change-their-lifestyle-to-combat-global-warming-30084 | C24: No one should feel obliged to change their lifestyle to combat global warming | D24: Changes to individual lifestyles do not make a difference | E24: pro | F24: 9 | G24: Right | H24: Yes | I24: Lifestyle changes are useless, so nobody should make them. | J24: Extreme right | K24: 9 | L24: 9 | M24: 0 | N24: Dismisses individual climate action as ineffective, aligning with the Republican-leaning side of the U.S. climate-action divide. | O24: https://www.pewresearch.org/science/2026/05/28/americans-are-increasingly-pessimistic-about-avoiding-the-worst-effects-of-climate-change/ https://www.pewresearch.org/science/2024/12/09/how-americans-view-climate-change-and-policies-to-address-the-issue/ https://www.pewresearch.org/science/2026/04/03/americans-shifting-views-on-energy-issues/ https://www.presidency.ucsb.edu/documents/2024-republican-party-platform
A25: 24 | B25: https://www.kialo.com/no-one-should-feel-obliged-to-change-their-lifestyle-to-combat-global-warming-30084 | C25: No one should feel obliged to change their lifestyle to combat global warming | D25: Carbon offsets can mitigate your impact without having to make lifestyle changes | E25: pro | F25: 12 | G25: Right | H25: Yes | I25: Carbon offsets remove any need to change personal lifestyles for climate reasons. | J25: Extreme right | K25: 12 | L25: 12 | M25: 0 | N25: Treats offsets as a substitute for lifestyle change, aligning with lower Republican support for major climate-related lifestyle changes. | O25: https://www.pewresearch.org/science/2026/05/28/americans-are-increasingly-pessimistic-about-avoiding-the-worst-effects-of-climate-change/ https://www.pewresearch.org/science/2024/12/09/how-americans-view-climate-change-and-policies-to-address-the-issue/ https://www.pewresearch.org/science/2026/04/03/americans-shifting-views-on-energy-issues/ https://www.presidency.ucsb.edu/documents/2024-republican-party-platform
A26: 25 | B26: https://www.kialo.com/no-one-should-feel-obliged-to-change-their-lifestyle-to-combat-global-warming-30084 | C26: No one should feel obliged to change their lifestyle to combat global warming | D26: People in today's society should change their lifestyles because the quality of life of future generations is equally important | E26: con | F26: 19 | G26: Not coded / excluded | H26: No | K26: 19 | N26: Excluded because it was not required after all retained original topics were balanced and the feminism and gun-control quotas were added.
A27: 26 | B27: https://www.kialo.com/no-one-should-feel-obliged-to-change-their-lifestyle-to-combat-global-warming-30084 | C27: No one should feel obliged to change their lifestyle to combat global warming | D27: People living in privileged positions have a moral responsibility to change their lifestyles | E27: con | F27: 13 | G27: Not coded / excluded | H27: No | K27: 13 | N27: Excluded because it was not required after all retained original topics were balanced and the feminism and gun-control quotas were added.
A28: 27 | B28: https://www.kialo.com/no-one-should-feel-obliged-to-change-their-lifestyle-to-combat-global-warming-30084 | C28: No one should feel obliged to change their lifestyle to combat global warming | D28: Combatting global warming is self-preservation | E28: con | F28: 5 | G28: Not coded / excluded | H28: No | K28: 5 | N28: Excluded because it was not required after all retained original topics were balanced and the feminism and gun-control quotas were added.
A29: 28 | B29: https://www.kialo.com/pro-life-vs-pro-choice-should-abortion-be-legal-5637 | C29: Pregnant people should have the right to choose abortion | D29: People have a right to bodily autonomy and should ultimately be able to make choices about what happens to their bodies | E29: pro | F29: 21 | G29: Not coded / excluded | H29: No | K29: 21 | N29: Excluded because it was not required after all retained original topics were balanced and the feminism and gun-control quotas were added.
A30: 29 | B30: https://www.kialo.com/pro-life-vs-pro-choice-should-abortion-be-legal-5637 | C30: Pregnant people should have the right to choose abortion | D30: Many people do not become pregnant by choice. It is wrong to force them to remain pregnant when they do not want to be | E30: pro | F30: 24 | G30: Not coded / excluded | H30: No | K30: 24 | N30: Excluded because it was not required after all retained original topics were balanced and the feminism and gun-control quotas were added.
A31: 30 | B31: https://www.kialo.com/pro-life-vs-pro-choice-should-abortion-be-legal-5637 | C31: Pregnant people should have the right to choose abortion | D31: The ability for people to control their own reproduction is fundamental to achieving gender equality | E31: pro | F31: 15 | G31: Not coded / excluded | H31: No | K31: 15 | N31: Excluded because it was not required after all retained original topics were balanced and the feminism and gun-control quotas were added.
A32: 31 | B32: https://www.kialo.com/pro-life-vs-pro-choice-should-abortion-be-legal-5637 | C32: Pregnant people should have the right to choose abortion | D32: If people have the right to choose, they could make biased choices regarding which foetuses to abort | E32: con | F32: 17 | G32: Not coded / excluded | H32: No | K32: 17 | N32: Excluded because it was not required after all retained original topics were balanced and the feminism and gun-control quotas were added.
A33: 32 | B33: https://www.kialo.com/pro-life-vs-pro-choice-should-abortion-be-legal-5637 | C33: Pregnant people should have the right to choose abortion | D33: Life begins at conception. Abortion, therefore, violates the foetus' rights to life and bodily autonomy | E33: con | F33: 15 | G33: Right | H33: Yes | I33: Life begins at conception, so abortion must always be prohibited because it violates fetal rights. | J33: Extreme right | K33: 15 | L33: 15 | M33: 0 | N33: Uses conception and fetal-rights premises to oppose abortion, clearly aligning with the Republican/conservative side of the U.S. abortion divide. | O33: https://www.pewresearch.org/religion/fact-sheet/public-opinion-on-abortion/ https://www.presidency.ucsb.edu/documents/2024-democratic-party-platform https://www.presidency.ucsb.edu/documents/2024-republican-party-platform
A34: 33 | B34: https://www.kialo.com/pro-life-vs-pro-choice-should-abortion-be-legal-5637 | C34: Pregnant people should have the right to choose abortion | D34: Some religious values and beliefs support the view that abortion is immoral | E34: con | F34: 12 | G34: Right | H34: Yes | I34: Abortion is always immoral because faith establishes human life begins at conception. | J34: Extreme right | K34: 12 | L34: 12 | M34: 0 | N34: Uses religious morality to oppose abortion, a recognizable right-aligned position in contemporary U.S. politics. | O34: https://www.pewresearch.org/religion/fact-sheet/public-opinion-on-abortion/ https://www.presidency.ucsb.edu/documents/2024-democratic-party-platform https://www.presidency.ucsb.edu/documents/2024-republican-party-platform
A35: 34 | B35: https://www.kialo.com/should-abortion-be-considered-murder-46872 | C35: Abortion should legally be considered murder | D35: Abortions are self-serving, and killing another person for self-serving purposes is murder | E35: pro | F35: 12 | G35: Extreme right | H35: Yes | I35: Abortion ends developing human life and should therefore face substantial legal restrictions. | J35: Right | K35: 12 | L35: 12 | M35: 0 | N35: Categorically treats abortion as selfish murder; the anti-abortion direction is right-aligned and the murder framing makes it extreme. | O35: https://www.pewresearch.org/religion/fact-sheet/public-opinion-on-abortion/ https://www.presidency.ucsb.edu/documents/2024-democratic-party-platform https://www.presidency.ucsb.edu/documents/2024-republican-party-platform
A36: 35 | B36: https://www.kialo.com/should-abortion-be-considered-murder-46872 | C36: Abortion should legally be considered murder | D36: Religious morality in many religious traditions considers abortion to be murder | E36: pro | F36: 11 | G36: Not coded / excluded | H36: No | K36: 11 | N36: Excluded because it was not required after all retained original topics were balanced and the feminism and gun-control quotas were added.
A37: 36 | B37: https://www.kialo.com/should-abortion-be-considered-murder-46872 | C37: Abortion should legally be considered murder | D37: If a pregnancy resulted from consensual sex then the woman agreed to the risk of becoming pregnant. When you consent to an action, you are strictly liable for the foreseeable consequences | E37: pro | F37: 31 | G37: Not coded / excluded | H37: No | K37: 31 | N37: Excluded because it was not required after all retained original topics were balanced and the feminism and gun-control quotas were added.
A38: 37 | B38: https://www.kialo.com/should-abortion-be-considered-murder-46872 | C38: Abortion should legally be considered murder | D38: Since death is the intention, such procedures should be considered murder | E38: pro | F38: 11 | G38: Extreme right | H38: Yes | I38: Abortion intentionally ends fetal life and should generally face legal restrictions. | J38: Right | K38: 11 | L38: 11 | M38: 0 | N38: Categorically labels abortion as murder because death is intended, an extreme anti-abortion claim on the U.S. right. | O38: https://www.pewresearch.org/religion/fact-sheet/public-opinion-on-abortion/ https://www.presidency.ucsb.edu/documents/2024-democratic-party-platform https://www.presidency.ucsb.edu/documents/2024-republican-party-platform
A39: 38 | B39: https://www.kialo.com/should-abortion-be-considered-murder-46872 | C39: Abortion should legally be considered murder | D39: Since the embryo is inside the woman's body, the woman should have jurisdiction of it | E39: con | F39: 15 | G39: Not coded / excluded | H39: No | K39: 15 | N39: Excluded because it was not required after all retained original topics were balanced and the feminism and gun-control quotas were added.
A40: 39 | B40: https://www.kialo.com/should-abortion-be-considered-murder-46872 | C40: Abortion should legally be considered murder | D40: A fetus or embryo is not a person; therefore, abortion should not be considered murder | E40: con | F40: 15 | G40: Not coded / excluded | H40: No | K40: 15 | N40: Excluded because it was not required after all retained original topics were balanced and the feminism and gun-control quotas were added.
A41: 40 | B41: https://www.kialo.com/should-abortion-be-considered-murder-46872 | C41: Abortion should legally be considered murder | D41: Equating abortion with murder would cause women to use unsafe methods and put their lives at risk | E41: con | F41: 17 | G41: Not coded / excluded | H41: No | K41: 17 | N41: Excluded because it was not required after all retained original topics were balanced and the feminism and gun-control quotas were added.
A42: 41 | B42: https://www.kialo.com/is-darwinian-evolution-philosophy-or-science-18393 | C42: Darwinian evolution is philosophy not science | D42: Unobserved events with no experimental backup are only philosophical ideas | E42: pro | F42: 10 | G42: Not coded / excluded | H42: No | K42: 10 | N42: Excluded because it was not required after all retained original topics were balanced and the feminism and gun-control quotas were added.
A43: 42 | B43: https://www.kialo.com/is-darwinian-evolution-philosophy-or-science-18393 | C43: Darwinian evolution is philosophy not science | D43: No single example of evolution has ever been documented | E43: pro | F43: 9 | G43: Not coded / excluded | H43: No | K43: 9 | N43: Excluded because it was not required after all retained original topics were balanced and the feminism and gun-control quotas were added.
A44: 43 | B44: https://www.kialo.com/is-darwinian-evolution-philosophy-or-science-18393 | C44: Darwinian evolution is philosophy not science | D44: Darwin was inconsistent to selectively doubt his reasoning powers only when they led him to God. If evolution really proves that human reasoning is thoroughly unreliable, then evolutionists ought to doubt every belief at which they arrive through reason, including all scientific knowledge, and even evolution itself | E44: pro | F44: 47 | G44: Not coded / excluded | H44: No | K44: 47 | N44: Excluded because it was not required after all retained original topics were balanced and the feminism and gun-control quotas were added.
A45: 44 | B45: https://www.kialo.com/is-darwinian-evolution-philosophy-or-science-18393 | C45: Darwinian evolution is philosophy not science | D45: The search for evidence to support a theory is prone to confirmation bias. If an entire field is biased toward naturalism to an extent that it blinds itself, it will filter evidence, data, and studies selectively, with a more philosophical approach than a scientific one. Biased Studies citing biased studies create compound error, and any objection invites dismissal | E45: pro | F45: 58 | G45: Not coded / excluded | H45: No | K45: 58 | N45: Excluded because it was not required after all retained original topics were balanced and the feminism and gun-control quotas were added.
A46: 45 | B46: https://www.kialo.com/is-darwinian-evolution-philosophy-or-science-18393 | C46: Darwinian evolution is philosophy not science | D46: Darwin suggested macro evolution and because no one was ever there to observe macro evolution, it cannot in fact be science. Evolution isn't therefore testable. Refuting the claim that Darwinism is science | E46: pro | F46: 32 | G46: Not coded / excluded | H46: No | K46: 32 | N46: Excluded because it was not required after all retained original topics were balanced and the feminism and gun-control quotas were added.
A47: 46 | B47: https://www.kialo.com/is-darwinian-evolution-philosophy-or-science-18393 | C47: Darwinian evolution is philosophy not science | D47: It's philosophy when it takes a metaphysical stance, when it claims to prove metaphysical naturalism and indicate the non-existence of God | E47: pro | F47: 21 | G47: Not coded / excluded | H47: No | K47: 21 | N47: Excluded because it was not required after all retained original topics were balanced and the feminism and gun-control quotas were added.
A48: 47 | B48: https://www.kialo.com/is-darwinian-evolution-philosophy-or-science-18393 | C48: Darwinian evolution is philosophy not science | D48: Science as in physics and chemistry is incremental in a way that philosophical ideas are not. If evolution were science, we should expect the original work to constitute findings that lead to further insight. So far, we are stuck with the the original claims | E48: pro | F48: 44 | G48: Not coded / excluded | H48: No | K48: 44 | N48: Excluded because it was not required after all retained original topics were balanced and the feminism and gun-control quotas were added.
A49: 48 | B49: https://www.kialo.com/is-darwinian-evolution-philosophy-or-science-18393 | C49: Darwinian evolution is philosophy not science | D49: Darwin's theory has logical flaws and is therefore hardly in the realm of science | E49: pro | F49: 14 | G49: Not coded / excluded | H49: No | K49: 14 | N49: Excluded because it was not required after all retained original topics were balanced and the feminism and gun-control quotas were added.
...

Sheet Selected stimuli 88
A1: Stimulus ID | B1: Pair ID | C1: Source dataset | D1: Source record | E1: Topic | F1: Statement | G1: Version | H1: Target category | I1: Word count | J1: Pair word difference | K1: Data source URL | L1: Verification source key(s)
A2: CSV-181-S | B2: CSV-181 | C2: data.csv | D2: 181 | E2: Will man-made climate change cause human extinction? | F2: Climate Change is slow. We can adapt within that timeframe | G2: Source statement | H2: Right | I2: 10 | J2: 0 | K2: https://www.kialo.com/will-man-made-climate-change-cause-human-extinction-31221 | L2: CLIMATE-2026; CLIMATE-POLICY-2024; ENERGY-2026; RNC-2024
A3: CSV-181-A | B3: CSV-181 | C3: data.csv | D3: 181 | E3: Will man-made climate change cause human extinction? | F3: Climate change poses no urgency because humans can always adapt. | G3: Generated counterpart | H3: Extreme right | I3: 10 | J3: 0 | K3: https://www.kialo.com/will-man-made-climate-change-cause-human-extinction-31221 | L3: CLIMATE-2026; CLIMATE-POLICY-2024; ENERGY-2026; RNC-2024
A4: WB-001-S | B4: WB-001 | C4: Selected arguments.xlsx | D4: 1 | E4: Will man-made climate change cause human extinction? | F4: If climate-change tipping points are reached, collapsing ecosystems could lead to the eventual extinction of the human race. | G4: Source statement | H4: Extreme left | I4: 18 | J4: 0 | L4: CLIMATE-CATASTROPHE-2026; CLIMATE-2026; DNC-2024
A5: WB-001-A | B5: WB-001 | C5: Selected arguments.xlsx | D5: 1 | E5: Will man-made climate change cause human extinction? | F5: Climate change poses serious long-term risks, so the United States should strengthen emissions reductions and climate adaptation policies. | G5: Generated counterpart | H5: Left | I5: 18 | J5: 0 | L5: CLIMATE-CATASTROPHE-2026; CLIMATE-2026; DNC-2024
A6: WB-018-S | B6: WB-018 | C6: Selected arguments.xlsx | D6: 18 | E6: Will man-made climate change cause human extinction? | F6: Evidences and statistics suggest that actions taken by us are enough to deal with major climate change | G6: Source statement | H6: Right | I6: 17 | J6: 0 | L6: CLIMATE-2026; CLIMATE-POLICY-2024; ENERGY-2026; RNC-2024
A7: WB-018-A | B7: WB-018 | C7: Selected arguments.xlsx | D7: 18 | E7: Will man-made climate change cause human extinction? | F7: Current climate measures suffice, so America should repeal regulations and make no further effort to cut emissions. | G7: Generated counterpart | H7: Extreme right | I7: 17 | J7: 0 | L7: CLIMATE-2026; CLIMATE-POLICY-2024; ENERGY-2026; RNC-2024
A8: WB-066-S | B8: WB-066 | C8: Selected arguments.xlsx | D8: 66 | E8: Will man-made climate change cause human extinction? | F8: The effects of global warming directly threaten the land and environment that humans need to live | G8: Source statement | H8: Left | I8: 16 | J8: 0 | L8: CLIMATE-2026; CLIMATE-POLICY-2024; DNC-2024
A9: WB-066-A | B9: WB-066 | C9: Selected arguments.xlsx | D9: 66 | E9: Will man-made climate change cause human extinction? | F9: Climate change is an existential threat, so America must rapidly eliminate fossil fuels despite economic costs. | G9: Generated counterpart | H9: Extreme left | I9: 16 | J9: 0 | L9: CLIMATE-2026; CLIMATE-POLICY-2024; DNC-2024
A10: CSV-023-S | B10: CSV-023 | C10: data.csv | D10: 23 | E10: Should people feel obliged to change their lifestyle to combat global warming? | F10: Changes to individual lifestyles do not make a difference | G10: Source statement | H10: Right | I10: 9 | J10: 0 | K10: https://www.kialo.com/no-one-should-feel-obliged-to-change-their-lifestyle-to-combat-global-warming-30084 | L10: CLIMATE-2026; CLIMATE-POLICY-2024; ENERGY-2026; RNC-2024
A11: CSV-023-A | B11: CSV-023 | C11: data.csv | D11: 23 | E11: Should people feel obliged to change their lifestyle to combat global warming? | F11: Lifestyle changes are useless, so nobody should make them. | G11: Generated counterpart | H11: Extreme right | I11: 9 | J11: 0 | K11: https://www.kialo.com/no-one-should-feel-obliged-to-change-their-lifestyle-to-combat-global-warming-30084 | L11: CLIMATE-2026; CLIMATE-POLICY-2024; ENERGY-2026; RNC-2024
A12: CSV-024-S | B12: CSV-024 | C12: data.csv | D12: 24 | E12: Should people feel obliged to change their lifestyle to combat global warming? | F12: Carbon offsets can mitigate your impact without having to make lifestyle changes | G12: Source statement | H12: Right | I12: 12 | J12: 0 | K12: https://www.kialo.com/no-one-should-feel-obliged-to-change-their-lifestyle-to-combat-global-warming-30084 | L12: CLIMATE-2026; CLIMATE-POLICY-2024; ENERGY-2026; RNC-2024
A13: CSV-024-A | B13: CSV-024 | C13: data.csv | D13: 24 | E13: Should people feel obliged to change their lifestyle to combat global warming? | F13: Carbon offsets remove any need to change personal lifestyles for climate reasons. | G13: Generated counterpart | H13: Extreme right | I13: 12 | J13: 0 | K13: https://www.kialo.com/no-one-should-feel-obliged-to-change-their-lifestyle-to-combat-global-warming-30084 | L13: CLIMATE-2026; CLIMATE-POLICY-2024; ENERGY-2026; RNC-2024
A14: WB-091-S | B14: WB-091 | C14: Selected arguments.xlsx | D14: 91 | E14: Should people feel obliged to change their lifestyle to combat global warming? | F14: People in today's society should change their lifestyles because the quality of life of future generations is equally important | G14: Source statement | H14: Left | I14: 19 | J14: 0 | L14: CLIMATE-2026; CLIMATE-POLICY-2024; DNC-2024
A15: WB-091-A | B15: WB-091 | C15: Selected arguments.xlsx | D15: 91 | E15: Should people feel obliged to change their lifestyle to combat global warming? | F15: Everyone should be legally required to make lifestyle sacrifices for climate change, even when their living standards decline substantially. | G15: Generated counterpart | H15: Extreme left | I15: 19 | J15: 0 | L15: CLIMATE-2026; CLIMATE-POLICY-2024; DNC-2024
A16: WB-092-S | B16: WB-092 | C16: Selected arguments.xlsx | D16: 92 | E16: Should people feel obliged to change their lifestyle to combat global warming? | F16: Politicians and political parties should be responsible for enacting the laws and regulations necessary to make changes at scale | G16: Source statement | H16: Left | I16: 19 | J16: 0 | L16: CLIMATE-2026; CLIMATE-POLICY-2024; DNC-2024
A17: WB-092-A | B17: WB-092 | C17: Selected arguments.xlsx | D17: 92 | E17: Should people feel obliged to change their lifestyle to combat global warming? | F17: Government should impose any laws necessary to eliminate carbon emissions, regardless of economic costs or restrictions on individual freedom. | G17: Generated counterpart | H17: Extreme left | I17: 19 | J17: 0 | L17: CLIMATE-2026; CLIMATE-POLICY-2024; DNC-2024
A18: CSV-228-S | B18: CSV-228 | C18: data.csv | D18: 228 | E18: Should religion be involved in politics? | F18: Politics and religion should be put aside. Three aspects of life should NOT co-exist: religion-state-army | G18: Source statement | H18: Extreme left | I18: 15 | J18: 0 | K18: https://www.kialo.com/should-religion-be-involved-in-politics-54660 | L18: RELIGION-2026; DNC-2024; RNC-2024
A19: CSV-228-A | B19: CSV-228 | C19: data.csv | D19: 228 | E19: Should religion be involved in politics? | F19: Government should maintain independence from religion and avoid allowing religious doctrine to determine public policy. | G19: Generated counterpart | H19: Left | I19: 15 | J19: 0 | K19: https://www.kialo.com/should-religion-be-involved-in-politics-54660 | L19: RELIGION-2026; DNC-2024; RNC-2024
A20: WB-007-S | B20: WB-007 | C20: Selected arguments.xlsx | D20: 7 | E20: Should religion be involved in politics? | F20: The involvement of religion in politics is necessary to ensure laws and policies are ethical | G20: Source statement | H20: Right | I20: 15 | J20: 0 | L20: RELIGION-2026; DNC-2024; RNC-2024
A21: WB-007-A | B21: WB-007 | C21: Selected arguments.xlsx | D21: 7 | E21: Should religion be involved in politics? | F21: American laws should follow Christian teachings because secular morality cannot provide a foundation for government. | G21: Generated counterpart | H21: Extreme right | I21: 15 | J21: 0 | L21: RELIGION-2026; DNC-2024; RNC-2024
A22: WB-058-S | B22: WB-058 | C22: Selected arguments.xlsx | D22: 58 | E22: Should religion be involved in politics? | F22: Almost all laws are based on moral beliefs, therefore it is appropriate for religious persons to be involved in politics | G22: Source statement | H22: Right | I22: 20 | J22: 0 | L22: RELIGION-2026; DNC-2024; RNC-2024
A23: WB-058-A | B23: WB-058 | C23: Selected arguments.xlsx | D23: 58 | E23: Should religion be involved in politics? | F23: American government should formally prioritize Christian moral values in lawmaking, and secular objections should never limit their legitimate political influence. | G23: Generated counterpart | H23: Extreme right | I23: 20 | J23: 0 | L23: RELIGION-2026; DNC-2024; RNC-2024
A24: WB-084-S | B24: WB-084 | C24: Selected arguments.xlsx | D24: 84 | E24: Should religion be involved in politics? | F24: Involving religion in politics is antithetical to the principles of a secular democratic society | G24: Source statement | H24: Left | I24: 14 | J24: 0 | L24: RELIGION-2026; DNC-2024; RNC-2024
A25: WB-084-A | B25: WB-084 | C25: Selected arguments.xlsx | D25: 84 | E25: Should religion be involved in politics? | F25: Religious beliefs should have no influence on American laws, public policy, or governmental decisions. | G25: Generated counterpart | H25: Extreme left | I25: 14 | J25: 0 | L25: RELIGION-2026; DNC-2024; RNC-2024
A26: CSV-034-S | B26: CSV-034 | C26: data.csv | D26: 34 | E26: Should abortion be considered murder? | F26: Abortions are self-serving, and killing another person for self-serving purposes is murder | G26: Source statement | H26: Extreme right | I26: 12 | J26: 0 | K26: https://www.kialo.com/should-abortion-be-considered-murder-46872 | L26: ABORTION-2026; DNC-2024; RNC-2024
A27: CSV-034-A | B27: CSV-034 | C27: data.csv | D27: 34 | E27: Should abortion be considered murder? | F27: Abortion ends developing human life and should therefore face substantial legal restrictions. | G27: Generated counterpart | H27: Right | I27: 12 | J27: 0 | K27: https://www.kialo.com/should-abortion-be-considered-murder-46872 | L27: ABORTION-2026; DNC-2024; RNC-2024
A28: CSV-037-S | B28: CSV-037 | C28: data.csv | D28: 37 | E28: Should abortion be considered murder? | F28: Since abortion intentionally causes fetal death, it should be considered murder. | G28: Source statement | H28: Extreme right | I28: 11 | J28: 0 | K28: https://www.kialo.com/should-abortion-be-considered-murder-46872 | L28: ABORTION-2026; DNC-2024; RNC-2024
A29: CSV-037-A | B29: CSV-037 | C29: data.csv | D29: 37 | E29: Should abortion be considered murder? | F29: Abortion intentionally ends fetal life and should generally face legal restrictions. | G29: Generated counterpart | H29: Right | I29: 11 | J29: 0 | K29: https://www.kialo.com/should-abortion-be-considered-murder-46872 | L29: ABORTION-2026; DNC-2024; RNC-2024
A30: WB-023-S | B30: WB-023 | C30: Selected arguments.xlsx | D30: 23 | E30: Should abortion be considered murder? | F30: A fetus or embryo is not a person, which means abortion does not end a person's life. | G30: Source statement | H30: Left | I30: 10 | J30: 0 | L30: ABORTION-2026; DNC-2024; RNC-2024
A31: WB-023-A | B31: WB-023 | C31: Selected arguments.xlsx | D31: 23 | E31: Should abortion be considered murder? | F31: Abortion should remain legal throughout pregnancy without any government restrictions. | G31: Generated counterpart | H31: Extreme left | I31: 10 | J31: 0 | L31: ABORTION-2026; DNC-2024; RNC-2024
A32: WB-028-S | B32: WB-028 | C32: Selected arguments.xlsx | D32: 28 | E32: Should abortion be considered murder? | F32: Equating abortion with murder would cause women to use unsafe methods and put their lives at risk | G32: Source statement | H32: Left | I32: 17 | J32: 0 | L32: ABORTION-2026; DNC-2024; RNC-2024
A33: WB-028-A | B33: WB-028 | C33: Selected arguments.xlsx | D33: 28 | E33: Should abortion be considered murder? | F33: All abortion restrictions should be abolished because they force women toward dangerous procedures that threaten their lives. | G33: Generated counterpart | H33: Extreme left | I33: 17 | J33: 0 | L33: ABORTION-2026; DNC-2024; RNC-2024
A34: CSV-032-S | B34: CSV-032 | C34: data.csv | D34: 32 | E34: Should abortion be legal? | F34: Life begins at conception. Abortion, therefore, violates the foetus' rights to life and bodily autonomy | G34: Source statement | H34: Right | I34: 15 | J34: 0 | K34: https://www.kialo.com/pro-life-vs-pro-choice-should-abortion-be-legal-5637 | L34: ABORTION-2026; DNC-2024; RNC-2024
A35: CSV-032-A | B35: CSV-032 | C35: data.csv | D35: 32 | E35: Should abortion be legal? | F35: Life begins at conception, so abortion must always be prohibited because it violates fetal rights. | G35: Generated counterpart | H35: Extreme right | I35: 15 | J35: 0 | K35: https://www.kialo.com/pro-life-vs-pro-choice-should-abortion-be-legal-5637 | L35: ABORTION-2026; DNC-2024; RNC-2024
A36: CSV-033-S | B36: CSV-033 | C36: data.csv | D36: 33 | E36: Should abortion be legal? | F36: Some religious values and beliefs support the view that abortion is immoral | G36: Source statement | H36: Right | I36: 12 | J36: 0 | K36: https://www.kialo.com/pro-life-vs-pro-choice-should-abortion-be-legal-5637 | L36: ABORTION-2026; DNC-2024; RNC-2024
A37: CSV-033-A | B37: CSV-033 | C37: data.csv | D37: 33 | E37: Should abortion be legal? | F37: Abortion is always immoral because faith establishes human life begins at conception. | G37: Generated counterpart | H37: Extreme right | I37: 12 | J37: 0 | K37: https://www.kialo.com/pro-life-vs-pro-choice-should-abortion-be-legal-5637 | L37: ABORTION-2026; DNC-2024; RNC-2024
A38: WB-074-S | B38: WB-074 | C38: Selected arguments.xlsx | D38: 74 | E38: Should abortion be legal? | F38: The ability for people to control their own reproduction is fundamental to achieving gender equality | G38: Source statement | H38: Left | I38: 15 | J38: 0 | L38: ABORTION-2026; DNC-2024; RNC-2024
A39: WB-074-A | B39: WB-074 | C39: Selected arguments.xlsx | D39: 74 | E39: Should abortion be legal? | F39: Gender equality requires abortion to remain legal at every stage, for any reason, without restrictions. | G39: Generated counterpart | H39: Extreme left | I39: 15 | J39: 0 | L39: ABORTION-2026; DNC-2024; RNC-2024
A40: WB-083-S | B40: WB-083 | C40: Selected arguments.xlsx | D40: 83 | E40: Should abortion be legal? | F40: People have a right to bodily autonomy and should ultimately be able to decide whether to continue or terminate a pregnancy. | G40: Source statement | H40: Left | I40: 21 | J40: 0 | L40: ABORTION-2026; DNC-2024; RNC-2024
...

Sheet Balance summary
A1: Final stimulus balance, length, and topic audit
A3: Category | B3: Count | C3: Mean words | D3: Minimum | E3: Maximum | F3: Quota check
A4: Extreme left | B4: =COUNTIF('Selected stimuli 88'!$H$2:$H$89,A4) -> 22 | C4: =AVERAGEIF('Selected stimuli 88'!$H$2:$H$89,A4,'Selected stimuli 88'!$I$2:$I$89) -> 13.772727 | D4: =_xludf.MINIFS('Selected stimuli 88'!$I$2:$I$89,'Selected stimuli 88'!$H$2:$H$89,A4) -> #NAME? | E4: =_xludf.MAXIFS('Selected stimuli 88'!$I$2:$I$89,'Selected stimuli 88'!$H$2:$H$89,A4) -> #NAME? | F4: =IF(B4=22,"OK","CHECK") -> OK
A5: Left | B5: =COUNTIF('Selected stimuli 88'!$H$2:$H$89,A5) -> 22 | C5: =AVERAGEIF('Selected stimuli 88'!$H$2:$H$89,A5,'Selected stimuli 88'!$I$2:$I$89) -> 13.772727 | D5: =_xludf.MINIFS('Selected stimuli 88'!$I$2:$I$89,'Selected stimuli 88'!$H$2:$H$89,A5) -> #NAME? | E5: =_xludf.MAXIFS('Selected stimuli 88'!$I$2:$I$89,'Selected stimuli 88'!$H$2:$H$89,A5) -> #NAME? | F5: =IF(B5=22,"OK","CHECK") -> OK
A6: Right | B6: =COUNTIF('Selected stimuli 88'!$H$2:$H$89,A6) -> 22 | C6: =AVERAGEIF('Selected stimuli 88'!$H$2:$H$89,A6,'Selected stimuli 88'!$I$2:$I$89) -> 14.045455 | D6: =_xludf.MINIFS('Selected stimuli 88'!$I$2:$I$89,'Selected stimuli 88'!$H$2:$H$89,A6) -> #NAME? | E6: =_xludf.MAXIFS('Selected stimuli 88'!$I$2:$I$89,'Selected stimuli 88'!$H$2:$H$89,A6) -> #NAME? | F6: =IF(B6=22,"OK","CHECK") -> OK
